<?xml version="1.0" encoding="UTF-8"?>
<!-- Generated by org.testng.reporters.JUnitReportReporter -->
<testsuite skipped="0" hostname="Vova-ПК" name="core.CreditCardValidationTest" tests="66" failures="18" timestamp="12 ноя 2017 04:13:59 GMT" time="1.527" errors="5">
  <testcase name="cvv" time="0.004" classname="core.CreditCardValidationTest"/>
  <testcase name="exp" time="0.000" classname="core.CreditCardValidationTest"/>
  <testcase name="luhn" time="0.003" classname="core.CreditCardValidationTest">
    <failure type="java.lang.AssertionError" message="
Expected: Luhn of: 5284398929973080, should be valid
     but: was &lt;false&gt;">
      <![CDATA[java.lang.AssertionError: 
Expected: Luhn of: 5284398929973080, should be valid
     but: was <false>
	at org.hamcrest.MatcherAssert.assertThat(MatcherAssert.java:18)
	at org.hamcrest.MatcherAssert.assertThat(MatcherAssert.java:6)
	at core.CreditCardValidationTest.luhn(CreditCardValidationTest.java:41)
	at sun.reflect.NativeMethodAccessorImpl.invoke0(Native Method)
	at sun.reflect.NativeMethodAccessorImpl.invoke(Unknown Source)
	at sun.reflect.DelegatingMethodAccessorImpl.invoke(Unknown Source)
	at java.lang.reflect.Method.invoke(Unknown Source)
	at org.testng.internal.MethodInvocationHelper.invokeMethod(MethodInvocationHelper.java:108)
	at org.testng.internal.Invoker.invokeMethod(Invoker.java:661)
	at org.testng.internal.Invoker.invokeTestMethod(Invoker.java:869)
	at org.testng.internal.Invoker.invokeTestMethods(Invoker.java:1193)
	at org.testng.internal.TestMethodWorker.invokeTestMethods(TestMethodWorker.java:126)
	at org.testng.internal.TestMethodWorker.run(TestMethodWorker.java:109)
	at org.testng.TestRunner.privateRun(TestRunner.java:744)
	at org.testng.TestRunner.run(TestRunner.java:602)
	at org.testng.SuiteRunner.runTest(SuiteRunner.java:380)
	at org.testng.SuiteRunner.runSequentially(SuiteRunner.java:375)
	at org.testng.SuiteRunner.privateRun(SuiteRunner.java:340)
	at org.testng.SuiteRunner.run(SuiteRunner.java:289)
	at org.testng.SuiteRunnerWorker.runSuite(SuiteRunnerWorker.java:52)
	at org.testng.SuiteRunnerWorker.run(SuiteRunnerWorker.java:86)
	at org.testng.TestNG.runSuitesSequentially(TestNG.java:1301)
	at org.testng.TestNG.runSuitesLocally(TestNG.java:1226)
	at org.testng.TestNG.runSuites(TestNG.java:1144)
	at org.testng.TestNG.run(TestNG.java:1115)
	at org.testng.remote.AbstractRemoteTestNG.run(AbstractRemoteTestNG.java:132)
	at org.testng.remote.RemoteTestNG.initAndRun(RemoteTestNG.java:230)
	at org.testng.remote.RemoteTestNG.main(RemoteTestNG.java:76)
]]>
    </failure>
  </testcase> <!-- luhn -->
  <testcase name="luhn" time="0.005" classname="core.CreditCardValidationTest">
    <failure type="java.lang.AssertionError" message="
Expected: Luhn of: 374259201906721, should be valid
     but: was &lt;false&gt;">
      <![CDATA[java.lang.AssertionError: 
Expected: Luhn of: 374259201906721, should be valid
     but: was <false>
	at org.hamcrest.MatcherAssert.assertThat(MatcherAssert.java:18)
	at org.hamcrest.MatcherAssert.assertThat(MatcherAssert.java:6)
	at core.CreditCardValidationTest.luhn(CreditCardValidationTest.java:41)
	at sun.reflect.NativeMethodAccessorImpl.invoke0(Native Method)
	at sun.reflect.NativeMethodAccessorImpl.invoke(Unknown Source)
	at sun.reflect.DelegatingMethodAccessorImpl.invoke(Unknown Source)
	at java.lang.reflect.Method.invoke(Unknown Source)
	at org.testng.internal.MethodInvocationHelper.invokeMethod(MethodInvocationHelper.java:108)
	at org.testng.internal.Invoker.invokeMethod(Invoker.java:661)
	at org.testng.internal.Invoker.invokeTestMethod(Invoker.java:869)
	at org.testng.internal.Invoker.invokeTestMethods(Invoker.java:1193)
	at org.testng.internal.TestMethodWorker.invokeTestMethods(TestMethodWorker.java:126)
	at org.testng.internal.TestMethodWorker.run(TestMethodWorker.java:109)
	at org.testng.TestRunner.privateRun(TestRunner.java:744)
	at org.testng.TestRunner.run(TestRunner.java:602)
	at org.testng.SuiteRunner.runTest(SuiteRunner.java:380)
	at org.testng.SuiteRunner.runSequentially(SuiteRunner.java:375)
	at org.testng.SuiteRunner.privateRun(SuiteRunner.java:340)
	at org.testng.SuiteRunner.run(SuiteRunner.java:289)
	at org.testng.SuiteRunnerWorker.runSuite(SuiteRunnerWorker.java:52)
	at org.testng.SuiteRunnerWorker.run(SuiteRunnerWorker.java:86)
	at org.testng.TestNG.runSuitesSequentially(TestNG.java:1301)
	at org.testng.TestNG.runSuitesLocally(TestNG.java:1226)
	at org.testng.TestNG.runSuites(TestNG.java:1144)
	at org.testng.TestNG.run(TestNG.java:1115)
	at org.testng.remote.AbstractRemoteTestNG.run(AbstractRemoteTestNG.java:132)
	at org.testng.remote.RemoteTestNG.initAndRun(RemoteTestNG.java:230)
	at org.testng.remote.RemoteTestNG.main(RemoteTestNG.java:76)
]]>
    </failure>
  </testcase> <!-- luhn -->
  <testcase name="exp" time="0.011" classname="core.CreditCardValidationTest">
    <failure type="java.lang.AssertionError" message="
Expected: Credit Card Exp: 03/17, should be not expired
     but: was &lt;false&gt;">
      <![CDATA[java.lang.AssertionError: 
Expected: Credit Card Exp: 03/17, should be not expired
     but: was <false>
	at org.hamcrest.MatcherAssert.assertThat(MatcherAssert.java:18)
	at org.hamcrest.MatcherAssert.assertThat(MatcherAssert.java:6)
	at core.CreditCardValidationTest.exp(CreditCardValidationTest.java:31)
	at sun.reflect.NativeMethodAccessorImpl.invoke0(Native Method)
	at sun.reflect.NativeMethodAccessorImpl.invoke(Unknown Source)
	at sun.reflect.DelegatingMethodAccessorImpl.invoke(Unknown Source)
	at java.lang.reflect.Method.invoke(Unknown Source)
	at org.testng.internal.MethodInvocationHelper.invokeMethod(MethodInvocationHelper.java:108)
	at org.testng.internal.Invoker.invokeMethod(Invoker.java:661)
	at org.testng.internal.Invoker.invokeTestMethod(Invoker.java:869)
	at org.testng.internal.Invoker.invokeTestMethods(Invoker.java:1193)
	at org.testng.internal.TestMethodWorker.invokeTestMethods(TestMethodWorker.java:126)
	at org.testng.internal.TestMethodWorker.run(TestMethodWorker.java:109)
	at org.testng.TestRunner.privateRun(TestRunner.java:744)
	at org.testng.TestRunner.run(TestRunner.java:602)
	at org.testng.SuiteRunner.runTest(SuiteRunner.java:380)
	at org.testng.SuiteRunner.runSequentially(SuiteRunner.java:375)
	at org.testng.SuiteRunner.privateRun(SuiteRunner.java:340)
	at org.testng.SuiteRunner.run(SuiteRunner.java:289)
	at org.testng.SuiteRunnerWorker.runSuite(SuiteRunnerWorker.java:52)
	at org.testng.SuiteRunnerWorker.run(SuiteRunnerWorker.java:86)
	at org.testng.TestNG.runSuitesSequentially(TestNG.java:1301)
	at org.testng.TestNG.runSuitesLocally(TestNG.java:1226)
	at org.testng.TestNG.runSuites(TestNG.java:1144)
	at org.testng.TestNG.run(TestNG.java:1115)
	at org.testng.remote.AbstractRemoteTestNG.run(AbstractRemoteTestNG.java:132)
	at org.testng.remote.RemoteTestNG.initAndRun(RemoteTestNG.java:230)
	at org.testng.remote.RemoteTestNG.main(RemoteTestNG.java:76)
]]>
    </failure>
  </testcase> <!-- exp -->
  <testcase name="luhn" time="0.004" classname="core.CreditCardValidationTest"/>
  <testcase name="luhn" time="0.004" classname="core.CreditCardValidationTest">
    <failure type="java.lang.AssertionError" message="
Expected: Luhn of: 5484398929973080, should be valid
     but: was &lt;false&gt;">
      <![CDATA[java.lang.AssertionError: 
Expected: Luhn of: 5484398929973080, should be valid
     but: was <false>
	at org.hamcrest.MatcherAssert.assertThat(MatcherAssert.java:18)
	at org.hamcrest.MatcherAssert.assertThat(MatcherAssert.java:6)
	at core.CreditCardValidationTest.luhn(CreditCardValidationTest.java:41)
	at sun.reflect.NativeMethodAccessorImpl.invoke0(Native Method)
	at sun.reflect.NativeMethodAccessorImpl.invoke(Unknown Source)
	at sun.reflect.DelegatingMethodAccessorImpl.invoke(Unknown Source)
	at java.lang.reflect.Method.invoke(Unknown Source)
	at org.testng.internal.MethodInvocationHelper.invokeMethod(MethodInvocationHelper.java:108)
	at org.testng.internal.Invoker.invokeMethod(Invoker.java:661)
	at org.testng.internal.Invoker.invokeTestMethod(Invoker.java:869)
	at org.testng.internal.Invoker.invokeTestMethods(Invoker.java:1193)
	at org.testng.internal.TestMethodWorker.invokeTestMethods(TestMethodWorker.java:126)
	at org.testng.internal.TestMethodWorker.run(TestMethodWorker.java:109)
	at org.testng.TestRunner.privateRun(TestRunner.java:744)
	at org.testng.TestRunner.run(TestRunner.java:602)
	at org.testng.SuiteRunner.runTest(SuiteRunner.java:380)
	at org.testng.SuiteRunner.runSequentially(SuiteRunner.java:375)
	at org.testng.SuiteRunner.privateRun(SuiteRunner.java:340)
	at org.testng.SuiteRunner.run(SuiteRunner.java:289)
	at org.testng.SuiteRunnerWorker.runSuite(SuiteRunnerWorker.java:52)
	at org.testng.SuiteRunnerWorker.run(SuiteRunnerWorker.java:86)
	at org.testng.TestNG.runSuitesSequentially(TestNG.java:1301)
	at org.testng.TestNG.runSuitesLocally(TestNG.java:1226)
	at org.testng.TestNG.runSuites(TestNG.java:1144)
	at org.testng.TestNG.run(TestNG.java:1115)
	at org.testng.remote.AbstractRemoteTestNG.run(AbstractRemoteTestNG.java:132)
	at org.testng.remote.RemoteTestNG.initAndRun(RemoteTestNG.java:230)
	at org.testng.remote.RemoteTestNG.main(RemoteTestNG.java:76)
]]>
    </failure>
  </testcase> <!-- luhn -->
  <testcase name="luhn" time="0.007" classname="core.CreditCardValidationTest">
    <failure type="java.lang.AssertionError" message="
Expected: Luhn of: 4961785148901, should be valid
     but: was &lt;false&gt;">
      <![CDATA[java.lang.AssertionError: 
Expected: Luhn of: 4961785148901, should be valid
     but: was <false>
	at org.hamcrest.MatcherAssert.assertThat(MatcherAssert.java:18)
	at org.hamcrest.MatcherAssert.assertThat(MatcherAssert.java:6)
	at core.CreditCardValidationTest.luhn(CreditCardValidationTest.java:41)
	at sun.reflect.NativeMethodAccessorImpl.invoke0(Native Method)
	at sun.reflect.NativeMethodAccessorImpl.invoke(Unknown Source)
	at sun.reflect.DelegatingMethodAccessorImpl.invoke(Unknown Source)
	at java.lang.reflect.Method.invoke(Unknown Source)
	at org.testng.internal.MethodInvocationHelper.invokeMethod(MethodInvocationHelper.java:108)
	at org.testng.internal.Invoker.invokeMethod(Invoker.java:661)
	at org.testng.internal.Invoker.invokeTestMethod(Invoker.java:869)
	at org.testng.internal.Invoker.invokeTestMethods(Invoker.java:1193)
	at org.testng.internal.TestMethodWorker.invokeTestMethods(TestMethodWorker.java:126)
	at org.testng.internal.TestMethodWorker.run(TestMethodWorker.java:109)
	at org.testng.TestRunner.privateRun(TestRunner.java:744)
	at org.testng.TestRunner.run(TestRunner.java:602)
	at org.testng.SuiteRunner.runTest(SuiteRunner.java:380)
	at org.testng.SuiteRunner.runSequentially(SuiteRunner.java:375)
	at org.testng.SuiteRunner.privateRun(SuiteRunner.java:340)
	at org.testng.SuiteRunner.run(SuiteRunner.java:289)
	at org.testng.SuiteRunnerWorker.runSuite(SuiteRunnerWorker.java:52)
	at org.testng.SuiteRunnerWorker.run(SuiteRunnerWorker.java:86)
	at org.testng.TestNG.runSuitesSequentially(TestNG.java:1301)
	at org.testng.TestNG.runSuitesLocally(TestNG.java:1226)
	at org.testng.TestNG.runSuites(TestNG.java:1144)
	at org.testng.TestNG.run(TestNG.java:1115)
	at org.testng.remote.AbstractRemoteTestNG.run(AbstractRemoteTestNG.java:132)
	at org.testng.remote.RemoteTestNG.initAndRun(RemoteTestNG.java:230)
	at org.testng.remote.RemoteTestNG.main(RemoteTestNG.java:76)
]]>
    </failure>
  </testcase> <!-- luhn -->
  <testcase name="type" time="0.005" classname="core.CreditCardValidationTest"/>
  <testcase name="type" time="0.003" classname="core.CreditCardValidationTest"/>
  <testcase name="cvv" time="0.000" classname="core.CreditCardValidationTest"/>
  <testcase name="exp" time="0.006" classname="core.CreditCardValidationTest">
    <failure type="java.lang.AssertionError" message="
Expected: Credit Card Exp: 03/16, should be not expired
     but: was &lt;false&gt;">
      <![CDATA[java.lang.AssertionError: 
Expected: Credit Card Exp: 03/16, should be not expired
     but: was <false>
	at org.hamcrest.MatcherAssert.assertThat(MatcherAssert.java:18)
	at org.hamcrest.MatcherAssert.assertThat(MatcherAssert.java:6)
	at core.CreditCardValidationTest.exp(CreditCardValidationTest.java:31)
	at sun.reflect.NativeMethodAccessorImpl.invoke0(Native Method)
	at sun.reflect.NativeMethodAccessorImpl.invoke(Unknown Source)
	at sun.reflect.DelegatingMethodAccessorImpl.invoke(Unknown Source)
	at java.lang.reflect.Method.invoke(Unknown Source)
	at org.testng.internal.MethodInvocationHelper.invokeMethod(MethodInvocationHelper.java:108)
	at org.testng.internal.Invoker.invokeMethod(Invoker.java:661)
	at org.testng.internal.Invoker.invokeTestMethod(Invoker.java:869)
	at org.testng.internal.Invoker.invokeTestMethods(Invoker.java:1193)
	at org.testng.internal.TestMethodWorker.invokeTestMethods(TestMethodWorker.java:126)
	at org.testng.internal.TestMethodWorker.run(TestMethodWorker.java:109)
	at org.testng.TestRunner.privateRun(TestRunner.java:744)
	at org.testng.TestRunner.run(TestRunner.java:602)
	at org.testng.SuiteRunner.runTest(SuiteRunner.java:380)
	at org.testng.SuiteRunner.runSequentially(SuiteRunner.java:375)
	at org.testng.SuiteRunner.privateRun(SuiteRunner.java:340)
	at org.testng.SuiteRunner.run(SuiteRunner.java:289)
	at org.testng.SuiteRunnerWorker.runSuite(SuiteRunnerWorker.java:52)
	at org.testng.SuiteRunnerWorker.run(SuiteRunnerWorker.java:86)
	at org.testng.TestNG.runSuitesSequentially(TestNG.java:1301)
	at org.testng.TestNG.runSuitesLocally(TestNG.java:1226)
	at org.testng.TestNG.runSuites(TestNG.java:1144)
	at org.testng.TestNG.run(TestNG.java:1115)
	at org.testng.remote.AbstractRemoteTestNG.run(AbstractRemoteTestNG.java:132)
	at org.testng.remote.RemoteTestNG.initAndRun(RemoteTestNG.java:230)
	at org.testng.remote.RemoteTestNG.main(RemoteTestNG.java:76)
]]>
    </failure>
  </testcase> <!-- exp -->
  <testcase name="exp" time="0.144" classname="core.CreditCardValidationTest">
    <error type="org.testng.internal.reflect.MethodMatcherException" message="
Data provider mismatch
Method: exp([Parameter{index=0, type=java.lang.String, declaredAnnotations=[]}, Parameter{index=1, type=java.lang.String, declaredAnnotations=[]}, Parameter{index=2, type=java.lang.String, declaredAnnotations=[]}, Parameter{index=3, type=java.lang.String, declaredAnnotations=[]}])
Arguments: [(java.lang.String)]">
      <![CDATA[org.testng.internal.reflect.MethodMatcherException: 
Data provider mismatch
Method: exp([Parameter{index=0, type=java.lang.String, declaredAnnotations=[]}, Parameter{index=1, type=java.lang.String, declaredAnnotations=[]}, Parameter{index=2, type=java.lang.String, declaredAnnotations=[]}, Parameter{index=3, type=java.lang.String, declaredAnnotations=[]}])
Arguments: [(java.lang.String)]
	at org.testng.internal.reflect.DataProviderMethodMatcher.getConformingArguments(DataProviderMethodMatcher.java:49)
	at org.testng.internal.Invoker.injectParameters(Invoker.java:1293)
	at org.testng.internal.Invoker.invokeTestMethods(Invoker.java:1187)
	at org.testng.internal.TestMethodWorker.invokeTestMethods(TestMethodWorker.java:126)
	at org.testng.internal.TestMethodWorker.run(TestMethodWorker.java:109)
	at org.testng.TestRunner.privateRun(TestRunner.java:744)
	at org.testng.TestRunner.run(TestRunner.java:602)
	at org.testng.SuiteRunner.runTest(SuiteRunner.java:380)
	at org.testng.SuiteRunner.runSequentially(SuiteRunner.java:375)
	at org.testng.SuiteRunner.privateRun(SuiteRunner.java:340)
	at org.testng.SuiteRunner.run(SuiteRunner.java:289)
	at org.testng.SuiteRunnerWorker.runSuite(SuiteRunnerWorker.java:52)
	at org.testng.SuiteRunnerWorker.run(SuiteRunnerWorker.java:86)
	at org.testng.TestNG.runSuitesSequentially(TestNG.java:1301)
	at org.testng.TestNG.runSuitesLocally(TestNG.java:1226)
	at org.testng.TestNG.runSuites(TestNG.java:1144)
	at org.testng.TestNG.run(TestNG.java:1115)
	at org.testng.remote.AbstractRemoteTestNG.run(AbstractRemoteTestNG.java:132)
	at org.testng.remote.RemoteTestNG.initAndRun(RemoteTestNG.java:230)
	at org.testng.remote.RemoteTestNG.main(RemoteTestNG.java:76)
]]>
    </error>
  </testcase> <!-- exp -->
  <testcase name="test02" time="0.005" classname="core.CreditCardValidationTest"/>
  <testcase name="luhn" time="0.003" classname="core.CreditCardValidationTest">
    <failure type="java.lang.AssertionError" message="
Expected: Luhn of: 6411933302679615, should be valid
     but: was &lt;false&gt;">
      <![CDATA[java.lang.AssertionError: 
Expected: Luhn of: 6411933302679615, should be valid
     but: was <false>
	at org.hamcrest.MatcherAssert.assertThat(MatcherAssert.java:18)
	at org.hamcrest.MatcherAssert.assertThat(MatcherAssert.java:6)
	at core.CreditCardValidationTest.luhn(CreditCardValidationTest.java:41)
	at sun.reflect.NativeMethodAccessorImpl.invoke0(Native Method)
	at sun.reflect.NativeMethodAccessorImpl.invoke(Unknown Source)
	at sun.reflect.DelegatingMethodAccessorImpl.invoke(Unknown Source)
	at java.lang.reflect.Method.invoke(Unknown Source)
	at org.testng.internal.MethodInvocationHelper.invokeMethod(MethodInvocationHelper.java:108)
	at org.testng.internal.Invoker.invokeMethod(Invoker.java:661)
	at org.testng.internal.Invoker.invokeTestMethod(Invoker.java:869)
	at org.testng.internal.Invoker.invokeTestMethods(Invoker.java:1193)
	at org.testng.internal.TestMethodWorker.invokeTestMethods(TestMethodWorker.java:126)
	at org.testng.internal.TestMethodWorker.run(TestMethodWorker.java:109)
	at org.testng.TestRunner.privateRun(TestRunner.java:744)
	at org.testng.TestRunner.run(TestRunner.java:602)
	at org.testng.SuiteRunner.runTest(SuiteRunner.java:380)
	at org.testng.SuiteRunner.runSequentially(SuiteRunner.java:375)
	at org.testng.SuiteRunner.privateRun(SuiteRunner.java:340)
	at org.testng.SuiteRunner.run(SuiteRunner.java:289)
	at org.testng.SuiteRunnerWorker.runSuite(SuiteRunnerWorker.java:52)
	at org.testng.SuiteRunnerWorker.run(SuiteRunnerWorker.java:86)
	at org.testng.TestNG.runSuitesSequentially(TestNG.java:1301)
	at org.testng.TestNG.runSuitesLocally(TestNG.java:1226)
	at org.testng.TestNG.runSuites(TestNG.java:1144)
	at org.testng.TestNG.run(TestNG.java:1115)
	at org.testng.remote.AbstractRemoteTestNG.run(AbstractRemoteTestNG.java:132)
	at org.testng.remote.RemoteTestNG.initAndRun(RemoteTestNG.java:230)
	at org.testng.remote.RemoteTestNG.main(RemoteTestNG.java:76)
]]>
    </failure>
  </testcase> <!-- luhn -->
  <testcase name="type" time="0.004" classname="core.CreditCardValidationTest"/>
  <testcase name="type" time="0.005" classname="core.CreditCardValidationTest"/>
  <testcase name="type" time="0.004" classname="core.CreditCardValidationTest">
    <failure type="java.lang.AssertionError" message="
Expected: Credit Card Type: MoldovaBank, should be valid
     but: was &lt;false&gt;">
      <![CDATA[java.lang.AssertionError: 
Expected: Credit Card Type: MoldovaBank, should be valid
     but: was <false>
	at org.hamcrest.MatcherAssert.assertThat(MatcherAssert.java:18)
	at org.hamcrest.MatcherAssert.assertThat(MatcherAssert.java:6)
	at core.CreditCardValidationTest.type(CreditCardValidationTest.java:26)
	at sun.reflect.NativeMethodAccessorImpl.invoke0(Native Method)
	at sun.reflect.NativeMethodAccessorImpl.invoke(Unknown Source)
	at sun.reflect.DelegatingMethodAccessorImpl.invoke(Unknown Source)
	at java.lang.reflect.Method.invoke(Unknown Source)
	at org.testng.internal.MethodInvocationHelper.invokeMethod(MethodInvocationHelper.java:108)
	at org.testng.internal.Invoker.invokeMethod(Invoker.java:661)
	at org.testng.internal.Invoker.invokeTestMethod(Invoker.java:869)
	at org.testng.internal.Invoker.invokeTestMethods(Invoker.java:1193)
	at org.testng.internal.TestMethodWorker.invokeTestMethods(TestMethodWorker.java:126)
	at org.testng.internal.TestMethodWorker.run(TestMethodWorker.java:109)
	at org.testng.TestRunner.privateRun(TestRunner.java:744)
	at org.testng.TestRunner.run(TestRunner.java:602)
	at org.testng.SuiteRunner.runTest(SuiteRunner.java:380)
	at org.testng.SuiteRunner.runSequentially(SuiteRunner.java:375)
	at org.testng.SuiteRunner.privateRun(SuiteRunner.java:340)
	at org.testng.SuiteRunner.run(SuiteRunner.java:289)
	at org.testng.SuiteRunnerWorker.runSuite(SuiteRunnerWorker.java:52)
	at org.testng.SuiteRunnerWorker.run(SuiteRunnerWorker.java:86)
	at org.testng.TestNG.runSuitesSequentially(TestNG.java:1301)
	at org.testng.TestNG.runSuitesLocally(TestNG.java:1226)
	at org.testng.TestNG.runSuites(TestNG.java:1144)
	at org.testng.TestNG.run(TestNG.java:1115)
	at org.testng.remote.AbstractRemoteTestNG.run(AbstractRemoteTestNG.java:132)
	at org.testng.remote.RemoteTestNG.initAndRun(RemoteTestNG.java:230)
	at org.testng.remote.RemoteTestNG.main(RemoteTestNG.java:76)
]]>
    </failure>
  </testcase> <!-- type -->
  <testcase name="type" time="0.003" classname="core.CreditCardValidationTest"/>
  <testcase name="type" time="0.005" classname="core.CreditCardValidationTest"/>
  <testcase name="type" time="0.004" classname="core.CreditCardValidationTest"/>
  <testcase name="type" time="0.003" classname="core.CreditCardValidationTest"/>
  <testcase name="cvv" time="0.602" classname="core.CreditCardValidationTest">
    <error type="org.testng.internal.reflect.MethodMatcherException" message="
Data provider mismatch
Method: cvv([Parameter{index=0, type=java.lang.String, declaredAnnotations=[]}, Parameter{index=1, type=java.lang.String, declaredAnnotations=[]}, Parameter{index=2, type=java.lang.String, declaredAnnotations=[]}, Parameter{index=3, type=java.lang.String, declaredAnnotations=[]}])
Arguments: [(java.lang.String)]">
      <![CDATA[org.testng.internal.reflect.MethodMatcherException: 
Data provider mismatch
Method: cvv([Parameter{index=0, type=java.lang.String, declaredAnnotations=[]}, Parameter{index=1, type=java.lang.String, declaredAnnotations=[]}, Parameter{index=2, type=java.lang.String, declaredAnnotations=[]}, Parameter{index=3, type=java.lang.String, declaredAnnotations=[]}])
Arguments: [(java.lang.String)]
	at org.testng.internal.reflect.DataProviderMethodMatcher.getConformingArguments(DataProviderMethodMatcher.java:49)
	at org.testng.internal.Invoker.injectParameters(Invoker.java:1293)
	at org.testng.internal.Invoker.invokeTestMethods(Invoker.java:1187)
	at org.testng.internal.TestMethodWorker.invokeTestMethods(TestMethodWorker.java:126)
	at org.testng.internal.TestMethodWorker.run(TestMethodWorker.java:109)
	at org.testng.TestRunner.privateRun(TestRunner.java:744)
	at org.testng.TestRunner.run(TestRunner.java:602)
	at org.testng.SuiteRunner.runTest(SuiteRunner.java:380)
	at org.testng.SuiteRunner.runSequentially(SuiteRunner.java:375)
	at org.testng.SuiteRunner.privateRun(SuiteRunner.java:340)
	at org.testng.SuiteRunner.run(SuiteRunner.java:289)
	at org.testng.SuiteRunnerWorker.runSuite(SuiteRunnerWorker.java:52)
	at org.testng.SuiteRunnerWorker.run(SuiteRunnerWorker.java:86)
	at org.testng.TestNG.runSuitesSequentially(TestNG.java:1301)
	at org.testng.TestNG.runSuitesLocally(TestNG.java:1226)
	at org.testng.TestNG.runSuites(TestNG.java:1144)
	at org.testng.TestNG.run(TestNG.java:1115)
	at org.testng.remote.AbstractRemoteTestNG.run(AbstractRemoteTestNG.java:132)
	at org.testng.remote.RemoteTestNG.initAndRun(RemoteTestNG.java:230)
	at org.testng.remote.RemoteTestNG.main(RemoteTestNG.java:76)
]]>
    </error>
  </testcase> <!-- cvv -->
  <testcase name="exp" time="0.000" classname="core.CreditCardValidationTest"/>
  <testcase name="cvv" time="0.000" classname="core.CreditCardValidationTest"/>
  <testcase name="exp" time="0.004" classname="core.CreditCardValidationTest"/>
  <testcase name="cvv" time="0.010" classname="core.CreditCardValidationTest"/>
  <testcase name="luhn" time="0.124" classname="core.CreditCardValidationTest">
    <error type="org.testng.internal.reflect.MethodMatcherException" message="
Data provider mismatch
Method: luhn([Parameter{index=0, type=java.lang.String, declaredAnnotations=[]}, Parameter{index=1, type=java.lang.String, declaredAnnotations=[]}, Parameter{index=2, type=java.lang.String, declaredAnnotations=[]}, Parameter{index=3, type=java.lang.String, declaredAnnotations=[]}])
Arguments: [(java.lang.String)]">
      <![CDATA[org.testng.internal.reflect.MethodMatcherException: 
Data provider mismatch
Method: luhn([Parameter{index=0, type=java.lang.String, declaredAnnotations=[]}, Parameter{index=1, type=java.lang.String, declaredAnnotations=[]}, Parameter{index=2, type=java.lang.String, declaredAnnotations=[]}, Parameter{index=3, type=java.lang.String, declaredAnnotations=[]}])
Arguments: [(java.lang.String)]
	at org.testng.internal.reflect.DataProviderMethodMatcher.getConformingArguments(DataProviderMethodMatcher.java:49)
	at org.testng.internal.Invoker.injectParameters(Invoker.java:1293)
	at org.testng.internal.Invoker.invokeTestMethods(Invoker.java:1187)
	at org.testng.internal.TestMethodWorker.invokeTestMethods(TestMethodWorker.java:126)
	at org.testng.internal.TestMethodWorker.run(TestMethodWorker.java:109)
	at org.testng.TestRunner.privateRun(TestRunner.java:744)
	at org.testng.TestRunner.run(TestRunner.java:602)
	at org.testng.SuiteRunner.runTest(SuiteRunner.java:380)
	at org.testng.SuiteRunner.runSequentially(SuiteRunner.java:375)
	at org.testng.SuiteRunner.privateRun(SuiteRunner.java:340)
	at org.testng.SuiteRunner.run(SuiteRunner.java:289)
	at org.testng.SuiteRunnerWorker.runSuite(SuiteRunnerWorker.java:52)
	at org.testng.SuiteRunnerWorker.run(SuiteRunnerWorker.java:86)
	at org.testng.TestNG.runSuitesSequentially(TestNG.java:1301)
	at org.testng.TestNG.runSuitesLocally(TestNG.java:1226)
	at org.testng.TestNG.runSuites(TestNG.java:1144)
	at org.testng.TestNG.run(TestNG.java:1115)
	at org.testng.remote.AbstractRemoteTestNG.run(AbstractRemoteTestNG.java:132)
	at org.testng.remote.RemoteTestNG.initAndRun(RemoteTestNG.java:230)
	at org.testng.remote.RemoteTestNG.main(RemoteTestNG.java:76)
]]>
    </error>
  </testcase> <!-- luhn -->
  <testcase name="luhn" time="0.003" classname="core.CreditCardValidationTest">
    <failure type="java.lang.AssertionError" message="
Expected: Luhn of: 5184398929973080, should be valid
     but: was &lt;false&gt;">
      <![CDATA[java.lang.AssertionError: 
Expected: Luhn of: 5184398929973080, should be valid
     but: was <false>
	at org.hamcrest.MatcherAssert.assertThat(MatcherAssert.java:18)
	at org.hamcrest.MatcherAssert.assertThat(MatcherAssert.java:6)
	at core.CreditCardValidationTest.luhn(CreditCardValidationTest.java:41)
	at sun.reflect.NativeMethodAccessorImpl.invoke0(Native Method)
	at sun.reflect.NativeMethodAccessorImpl.invoke(Unknown Source)
	at sun.reflect.DelegatingMethodAccessorImpl.invoke(Unknown Source)
	at java.lang.reflect.Method.invoke(Unknown Source)
	at org.testng.internal.MethodInvocationHelper.invokeMethod(MethodInvocationHelper.java:108)
	at org.testng.internal.Invoker.invokeMethod(Invoker.java:661)
	at org.testng.internal.Invoker.invokeTestMethod(Invoker.java:869)
	at org.testng.internal.Invoker.invokeTestMethods(Invoker.java:1193)
	at org.testng.internal.TestMethodWorker.invokeTestMethods(TestMethodWorker.java:126)
	at org.testng.internal.TestMethodWorker.run(TestMethodWorker.java:109)
	at org.testng.TestRunner.privateRun(TestRunner.java:744)
	at org.testng.TestRunner.run(TestRunner.java:602)
	at org.testng.SuiteRunner.runTest(SuiteRunner.java:380)
	at org.testng.SuiteRunner.runSequentially(SuiteRunner.java:375)
	at org.testng.SuiteRunner.privateRun(SuiteRunner.java:340)
	at org.testng.SuiteRunner.run(SuiteRunner.java:289)
	at org.testng.SuiteRunnerWorker.runSuite(SuiteRunnerWorker.java:52)
	at org.testng.SuiteRunnerWorker.run(SuiteRunnerWorker.java:86)
	at org.testng.TestNG.runSuitesSequentially(TestNG.java:1301)
	at org.testng.TestNG.runSuitesLocally(TestNG.java:1226)
	at org.testng.TestNG.runSuites(TestNG.java:1144)
	at org.testng.TestNG.run(TestNG.java:1115)
	at org.testng.remote.AbstractRemoteTestNG.run(AbstractRemoteTestNG.java:132)
	at org.testng.remote.RemoteTestNG.initAndRun(RemoteTestNG.java:230)
	at org.testng.remote.RemoteTestNG.main(RemoteTestNG.java:76)
]]>
    </failure>
  </testcase> <!-- luhn -->
  <testcase name="exp" time="0.000" classname="core.CreditCardValidationTest"/>
  <testcase name="type" time="0.003" classname="core.CreditCardValidationTest"/>
  <testcase name="luhn" time="0.003" classname="core.CreditCardValidationTest"/>
  <testcase name="exp" time="0.017" classname="core.CreditCardValidationTest">
    <failure type="java.lang.AssertionError" message="
Expected: Credit Card Exp: 03/17, should be not expired
     but: was &lt;false&gt;">
      <![CDATA[java.lang.AssertionError: 
Expected: Credit Card Exp: 03/17, should be not expired
     but: was <false>
	at org.hamcrest.MatcherAssert.assertThat(MatcherAssert.java:18)
	at org.hamcrest.MatcherAssert.assertThat(MatcherAssert.java:6)
	at core.CreditCardValidationTest.exp(CreditCardValidationTest.java:31)
	at sun.reflect.NativeMethodAccessorImpl.invoke0(Native Method)
	at sun.reflect.NativeMethodAccessorImpl.invoke(Unknown Source)
	at sun.reflect.DelegatingMethodAccessorImpl.invoke(Unknown Source)
	at java.lang.reflect.Method.invoke(Unknown Source)
	at org.testng.internal.MethodInvocationHelper.invokeMethod(MethodInvocationHelper.java:108)
	at org.testng.internal.Invoker.invokeMethod(Invoker.java:661)
	at org.testng.internal.Invoker.invokeTestMethod(Invoker.java:869)
	at org.testng.internal.Invoker.invokeTestMethods(Invoker.java:1193)
	at org.testng.internal.TestMethodWorker.invokeTestMethods(TestMethodWorker.java:126)
	at org.testng.internal.TestMethodWorker.run(TestMethodWorker.java:109)
	at org.testng.TestRunner.privateRun(TestRunner.java:744)
	at org.testng.TestRunner.run(TestRunner.java:602)
	at org.testng.SuiteRunner.runTest(SuiteRunner.java:380)
	at org.testng.SuiteRunner.runSequentially(SuiteRunner.java:375)
	at org.testng.SuiteRunner.privateRun(SuiteRunner.java:340)
	at org.testng.SuiteRunner.run(SuiteRunner.java:289)
	at org.testng.SuiteRunnerWorker.runSuite(SuiteRunnerWorker.java:52)
	at org.testng.SuiteRunnerWorker.run(SuiteRunnerWorker.java:86)
	at org.testng.TestNG.runSuitesSequentially(TestNG.java:1301)
	at org.testng.TestNG.runSuitesLocally(TestNG.java:1226)
	at org.testng.TestNG.runSuites(TestNG.java:1144)
	at org.testng.TestNG.run(TestNG.java:1115)
	at org.testng.remote.AbstractRemoteTestNG.run(AbstractRemoteTestNG.java:132)
	at org.testng.remote.RemoteTestNG.initAndRun(RemoteTestNG.java:230)
	at org.testng.remote.RemoteTestNG.main(RemoteTestNG.java:76)
]]>
    </failure>
  </testcase> <!-- exp -->
  <testcase name="cvv" time="0.010" classname="core.CreditCardValidationTest"/>
  <testcase name="cvv" time="0.000" classname="core.CreditCardValidationTest"/>
  <testcase name="type" time="0.004" classname="core.CreditCardValidationTest"/>
  <testcase name="cvv" time="0.010" classname="core.CreditCardValidationTest"/>
  <testcase name="cvv" time="0.000" classname="core.CreditCardValidationTest"/>
  <testcase name="luhn" time="0.005" classname="core.CreditCardValidationTest">
    <failure type="java.lang.AssertionError" message="
Expected: Luhn of: 6211933302679615, should be valid
     but: was &lt;false&gt;">
      <![CDATA[java.lang.AssertionError: 
Expected: Luhn of: 6211933302679615, should be valid
     but: was <false>
	at org.hamcrest.MatcherAssert.assertThat(MatcherAssert.java:18)
	at org.hamcrest.MatcherAssert.assertThat(MatcherAssert.java:6)
	at core.CreditCardValidationTest.luhn(CreditCardValidationTest.java:41)
	at sun.reflect.NativeMethodAccessorImpl.invoke0(Native Method)
	at sun.reflect.NativeMethodAccessorImpl.invoke(Unknown Source)
	at sun.reflect.DelegatingMethodAccessorImpl.invoke(Unknown Source)
	at java.lang.reflect.Method.invoke(Unknown Source)
	at org.testng.internal.MethodInvocationHelper.invokeMethod(MethodInvocationHelper.java:108)
	at org.testng.internal.Invoker.invokeMethod(Invoker.java:661)
	at org.testng.internal.Invoker.invokeTestMethod(Invoker.java:869)
	at org.testng.internal.Invoker.invokeTestMethods(Invoker.java:1193)
	at org.testng.internal.TestMethodWorker.invokeTestMethods(TestMethodWorker.java:126)
	at org.testng.internal.TestMethodWorker.run(TestMethodWorker.java:109)
	at org.testng.TestRunner.privateRun(TestRunner.java:744)
	at org.testng.TestRunner.run(TestRunner.java:602)
	at org.testng.SuiteRunner.runTest(SuiteRunner.java:380)
	at org.testng.SuiteRunner.runSequentially(SuiteRunner.java:375)
	at org.testng.SuiteRunner.privateRun(SuiteRunner.java:340)
	at org.testng.SuiteRunner.run(SuiteRunner.java:289)
	at org.testng.SuiteRunnerWorker.runSuite(SuiteRunnerWorker.java:52)
	at org.testng.SuiteRunnerWorker.run(SuiteRunnerWorker.java:86)
	at org.testng.TestNG.runSuitesSequentially(TestNG.java:1301)
	at org.testng.TestNG.runSuitesLocally(TestNG.java:1226)
	at org.testng.TestNG.runSuites(TestNG.java:1144)
	at org.testng.TestNG.run(TestNG.java:1115)
	at org.testng.remote.AbstractRemoteTestNG.run(AbstractRemoteTestNG.java:132)
	at org.testng.remote.RemoteTestNG.initAndRun(RemoteTestNG.java:230)
	at org.testng.remote.RemoteTestNG.main(RemoteTestNG.java:76)
]]>
    </failure>
  </testcase> <!-- luhn -->
  <testcase name="exp" time="0.010" classname="core.CreditCardValidationTest">
    <failure type="java.lang.AssertionError" message="
Expected: Credit Card Exp: 01/16, should be not expired
     but: was &lt;false&gt;">
      <![CDATA[java.lang.AssertionError: 
Expected: Credit Card Exp: 01/16, should be not expired
     but: was <false>
	at org.hamcrest.MatcherAssert.assertThat(MatcherAssert.java:18)
	at org.hamcrest.MatcherAssert.assertThat(MatcherAssert.java:6)
	at core.CreditCardValidationTest.exp(CreditCardValidationTest.java:31)
	at sun.reflect.NativeMethodAccessorImpl.invoke0(Native Method)
	at sun.reflect.NativeMethodAccessorImpl.invoke(Unknown Source)
	at sun.reflect.DelegatingMethodAccessorImpl.invoke(Unknown Source)
	at java.lang.reflect.Method.invoke(Unknown Source)
	at org.testng.internal.MethodInvocationHelper.invokeMethod(MethodInvocationHelper.java:108)
	at org.testng.internal.Invoker.invokeMethod(Invoker.java:661)
	at org.testng.internal.Invoker.invokeTestMethod(Invoker.java:869)
	at org.testng.internal.Invoker.invokeTestMethods(Invoker.java:1193)
	at org.testng.internal.TestMethodWorker.invokeTestMethods(TestMethodWorker.java:126)
	at org.testng.internal.TestMethodWorker.run(TestMethodWorker.java:109)
	at org.testng.TestRunner.privateRun(TestRunner.java:744)
	at org.testng.TestRunner.run(TestRunner.java:602)
	at org.testng.SuiteRunner.runTest(SuiteRunner.java:380)
	at org.testng.SuiteRunner.runSequentially(SuiteRunner.java:375)
	at org.testng.SuiteRunner.privateRun(SuiteRunner.java:340)
	at org.testng.SuiteRunner.run(SuiteRunner.java:289)
	at org.testng.SuiteRunnerWorker.runSuite(SuiteRunnerWorker.java:52)
	at org.testng.SuiteRunnerWorker.run(SuiteRunnerWorker.java:86)
	at org.testng.TestNG.runSuitesSequentially(TestNG.java:1301)
	at org.testng.TestNG.runSuitesLocally(TestNG.java:1226)
	at org.testng.TestNG.runSuites(TestNG.java:1144)
	at org.testng.TestNG.run(TestNG.java:1115)
	at org.testng.remote.AbstractRemoteTestNG.run(AbstractRemoteTestNG.java:132)
	at org.testng.remote.RemoteTestNG.initAndRun(RemoteTestNG.java:230)
	at org.testng.remote.RemoteTestNG.main(RemoteTestNG.java:76)
]]>
    </failure>
  </testcase> <!-- exp -->
  <testcase name="exp" time="0.004" classname="core.CreditCardValidationTest"/>
  <testcase name="cvv" time="0.006" classname="core.CreditCardValidationTest"/>
  <testcase name="exp" time="0.003" classname="core.CreditCardValidationTest">
    <failure type="java.lang.AssertionError" message="
Expected: Credit Card Exp: 05/17, should be not expired
     but: was &lt;false&gt;">
      <![CDATA[java.lang.AssertionError: 
Expected: Credit Card Exp: 05/17, should be not expired
     but: was <false>
	at org.hamcrest.MatcherAssert.assertThat(MatcherAssert.java:18)
	at org.hamcrest.MatcherAssert.assertThat(MatcherAssert.java:6)
	at core.CreditCardValidationTest.exp(CreditCardValidationTest.java:31)
	at sun.reflect.NativeMethodAccessorImpl.invoke0(Native Method)
	at sun.reflect.NativeMethodAccessorImpl.invoke(Unknown Source)
	at sun.reflect.DelegatingMethodAccessorImpl.invoke(Unknown Source)
	at java.lang.reflect.Method.invoke(Unknown Source)
	at org.testng.internal.MethodInvocationHelper.invokeMethod(MethodInvocationHelper.java:108)
	at org.testng.internal.Invoker.invokeMethod(Invoker.java:661)
	at org.testng.internal.Invoker.invokeTestMethod(Invoker.java:869)
	at org.testng.internal.Invoker.invokeTestMethods(Invoker.java:1193)
	at org.testng.internal.TestMethodWorker.invokeTestMethods(TestMethodWorker.java:126)
	at org.testng.internal.TestMethodWorker.run(TestMethodWorker.java:109)
	at org.testng.TestRunner.privateRun(TestRunner.java:744)
	at org.testng.TestRunner.run(TestRunner.java:602)
	at org.testng.SuiteRunner.runTest(SuiteRunner.java:380)
	at org.testng.SuiteRunner.runSequentially(SuiteRunner.java:375)
	at org.testng.SuiteRunner.privateRun(SuiteRunner.java:340)
	at org.testng.SuiteRunner.run(SuiteRunner.java:289)
	at org.testng.SuiteRunnerWorker.runSuite(SuiteRunnerWorker.java:52)
	at org.testng.SuiteRunnerWorker.run(SuiteRunnerWorker.java:86)
	at org.testng.TestNG.runSuitesSequentially(TestNG.java:1301)
	at org.testng.TestNG.runSuitesLocally(TestNG.java:1226)
	at org.testng.TestNG.runSuites(TestNG.java:1144)
	at org.testng.TestNG.run(TestNG.java:1115)
	at org.testng.remote.AbstractRemoteTestNG.run(AbstractRemoteTestNG.java:132)
	at org.testng.remote.RemoteTestNG.initAndRun(RemoteTestNG.java:230)
	at org.testng.remote.RemoteTestNG.main(RemoteTestNG.java:76)
]]>
    </failure>
  </testcase> <!-- exp -->
  <testcase name="cvv" time="0.010" classname="core.CreditCardValidationTest"/>
  <testcase name="exp" time="0.003" classname="core.CreditCardValidationTest"/>
  <testcase name="cvv" time="0.270" classname="core.CreditCardValidationTest"/>
  <testcase name="cvv" time="0.000" classname="core.CreditCardValidationTest"/>
  <testcase name="luhn" time="0.003" classname="core.CreditCardValidationTest">
    <failure type="java.lang.AssertionError" message="
Expected: Luhn of: 85247652465412, should be valid
     but: was &lt;false&gt;">
      <![CDATA[java.lang.AssertionError: 
Expected: Luhn of: 85247652465412, should be valid
     but: was <false>
	at org.hamcrest.MatcherAssert.assertThat(MatcherAssert.java:18)
	at org.hamcrest.MatcherAssert.assertThat(MatcherAssert.java:6)
	at core.CreditCardValidationTest.luhn(CreditCardValidationTest.java:41)
	at sun.reflect.NativeMethodAccessorImpl.invoke0(Native Method)
	at sun.reflect.NativeMethodAccessorImpl.invoke(Unknown Source)
	at sun.reflect.DelegatingMethodAccessorImpl.invoke(Unknown Source)
	at java.lang.reflect.Method.invoke(Unknown Source)
	at org.testng.internal.MethodInvocationHelper.invokeMethod(MethodInvocationHelper.java:108)
	at org.testng.internal.Invoker.invokeMethod(Invoker.java:661)
	at org.testng.internal.Invoker.invokeTestMethod(Invoker.java:869)
	at org.testng.internal.Invoker.invokeTestMethods(Invoker.java:1193)
	at org.testng.internal.TestMethodWorker.invokeTestMethods(TestMethodWorker.java:126)
	at org.testng.internal.TestMethodWorker.run(TestMethodWorker.java:109)
	at org.testng.TestRunner.privateRun(TestRunner.java:744)
	at org.testng.TestRunner.run(TestRunner.java:602)
	at org.testng.SuiteRunner.runTest(SuiteRunner.java:380)
	at org.testng.SuiteRunner.runSequentially(SuiteRunner.java:375)
	at org.testng.SuiteRunner.privateRun(SuiteRunner.java:340)
	at org.testng.SuiteRunner.run(SuiteRunner.java:289)
	at org.testng.SuiteRunnerWorker.runSuite(SuiteRunnerWorker.java:52)
	at org.testng.SuiteRunnerWorker.run(SuiteRunnerWorker.java:86)
	at org.testng.TestNG.runSuitesSequentially(TestNG.java:1301)
	at org.testng.TestNG.runSuitesLocally(TestNG.java:1226)
	at org.testng.TestNG.runSuites(TestNG.java:1144)
	at org.testng.TestNG.run(TestNG.java:1115)
	at org.testng.remote.AbstractRemoteTestNG.run(AbstractRemoteTestNG.java:132)
	at org.testng.remote.RemoteTestNG.initAndRun(RemoteTestNG.java:230)
	at org.testng.remote.RemoteTestNG.main(RemoteTestNG.java:76)
]]>
    </failure>
  </testcase> <!-- luhn -->
  <testcase name="exp" time="0.008" classname="core.CreditCardValidationTest"/>
  <testcase name="luhn" time="0.005" classname="core.CreditCardValidationTest"/>
  <testcase name="test01" time="0.009" classname="core.CreditCardValidationTest">
    <error type="java.lang.ArrayIndexOutOfBoundsException" message="1">
      <![CDATA[java.lang.ArrayIndexOutOfBoundsException: 1
	at core.CreditCardValidation.main(CreditCardValidation.java:48)
	at core.CreditCardValidationTest.test01(CreditCardValidationTest.java:45)
	at sun.reflect.NativeMethodAccessorImpl.invoke0(Native Method)
	at sun.reflect.NativeMethodAccessorImpl.invoke(Unknown Source)
	at sun.reflect.DelegatingMethodAccessorImpl.invoke(Unknown Source)
	at java.lang.reflect.Method.invoke(Unknown Source)
	at org.testng.internal.MethodInvocationHelper.invokeMethod(MethodInvocationHelper.java:108)
	at org.testng.internal.Invoker.invokeMethod(Invoker.java:661)
	at org.testng.internal.Invoker.invokeTestMethod(Invoker.java:869)
	at org.testng.internal.Invoker.invokeTestMethods(Invoker.java:1193)
	at org.testng.internal.TestMethodWorker.invokeTestMethods(TestMethodWorker.java:126)
	at org.testng.internal.TestMethodWorker.run(TestMethodWorker.java:109)
	at org.testng.TestRunner.privateRun(TestRunner.java:744)
	at org.testng.TestRunner.run(TestRunner.java:602)
	at org.testng.SuiteRunner.runTest(SuiteRunner.java:380)
	at org.testng.SuiteRunner.runSequentially(SuiteRunner.java:375)
	at org.testng.SuiteRunner.privateRun(SuiteRunner.java:340)
	at org.testng.SuiteRunner.run(SuiteRunner.java:289)
	at org.testng.SuiteRunnerWorker.runSuite(SuiteRunnerWorker.java:52)
	at org.testng.SuiteRunnerWorker.run(SuiteRunnerWorker.java:86)
	at org.testng.TestNG.runSuitesSequentially(TestNG.java:1301)
	at org.testng.TestNG.runSuitesLocally(TestNG.java:1226)
	at org.testng.TestNG.runSuites(TestNG.java:1144)
	at org.testng.TestNG.run(TestNG.java:1115)
	at org.testng.remote.AbstractRemoteTestNG.run(AbstractRemoteTestNG.java:132)
	at org.testng.remote.RemoteTestNG.initAndRun(RemoteTestNG.java:230)
	at org.testng.remote.RemoteTestNG.main(RemoteTestNG.java:76)
]]>
    </error>
  </testcase> <!-- test01 -->
  <testcase name="cvv" time="0.017" classname="core.CreditCardValidationTest">
    <failure type="java.lang.AssertionError" message="
Expected: Credit Card CVV: 1234, should be valid
     but: was &lt;false&gt;">
      <![CDATA[java.lang.AssertionError: 
Expected: Credit Card CVV: 1234, should be valid
     but: was <false>
	at org.hamcrest.MatcherAssert.assertThat(MatcherAssert.java:18)
	at org.hamcrest.MatcherAssert.assertThat(MatcherAssert.java:6)
	at core.CreditCardValidationTest.cvv(CreditCardValidationTest.java:36)
	at sun.reflect.NativeMethodAccessorImpl.invoke0(Native Method)
	at sun.reflect.NativeMethodAccessorImpl.invoke(Unknown Source)
	at sun.reflect.DelegatingMethodAccessorImpl.invoke(Unknown Source)
	at java.lang.reflect.Method.invoke(Unknown Source)
	at org.testng.internal.MethodInvocationHelper.invokeMethod(MethodInvocationHelper.java:108)
	at org.testng.internal.Invoker.invokeMethod(Invoker.java:661)
	at org.testng.internal.Invoker.invokeTestMethod(Invoker.java:869)
	at org.testng.internal.Invoker.invokeTestMethods(Invoker.java:1193)
	at org.testng.internal.TestMethodWorker.invokeTestMethods(TestMethodWorker.java:126)
	at org.testng.internal.TestMethodWorker.run(TestMethodWorker.java:109)
	at org.testng.TestRunner.privateRun(TestRunner.java:744)
	at org.testng.TestRunner.run(TestRunner.java:602)
	at org.testng.SuiteRunner.runTest(SuiteRunner.java:380)
	at org.testng.SuiteRunner.runSequentially(SuiteRunner.java:375)
	at org.testng.SuiteRunner.privateRun(SuiteRunner.java:340)
	at org.testng.SuiteRunner.run(SuiteRunner.java:289)
	at org.testng.SuiteRunnerWorker.runSuite(SuiteRunnerWorker.java:52)
	at org.testng.SuiteRunnerWorker.run(SuiteRunnerWorker.java:86)
	at org.testng.TestNG.runSuitesSequentially(TestNG.java:1301)
	at org.testng.TestNG.runSuitesLocally(TestNG.java:1226)
	at org.testng.TestNG.runSuites(TestNG.java:1144)
	at org.testng.TestNG.run(TestNG.java:1115)
	at org.testng.remote.AbstractRemoteTestNG.run(AbstractRemoteTestNG.java:132)
	at org.testng.remote.RemoteTestNG.initAndRun(RemoteTestNG.java:230)
	at org.testng.remote.RemoteTestNG.main(RemoteTestNG.java:76)
]]>
    </failure>
  </testcase> <!-- cvv -->
  <testcase name="luhn" time="0.006" classname="core.CreditCardValidationTest">
    <failure type="java.lang.AssertionError" message="
Expected: Luhn of: 5384398929973080, should be valid
     but: was &lt;false&gt;">
      <![CDATA[java.lang.AssertionError: 
Expected: Luhn of: 5384398929973080, should be valid
     but: was <false>
	at org.hamcrest.MatcherAssert.assertThat(MatcherAssert.java:18)
	at org.hamcrest.MatcherAssert.assertThat(MatcherAssert.java:6)
	at core.CreditCardValidationTest.luhn(CreditCardValidationTest.java:41)
	at sun.reflect.NativeMethodAccessorImpl.invoke0(Native Method)
	at sun.reflect.NativeMethodAccessorImpl.invoke(Unknown Source)
	at sun.reflect.DelegatingMethodAccessorImpl.invoke(Unknown Source)
	at java.lang.reflect.Method.invoke(Unknown Source)
	at org.testng.internal.MethodInvocationHelper.invokeMethod(MethodInvocationHelper.java:108)
	at org.testng.internal.Invoker.invokeMethod(Invoker.java:661)
	at org.testng.internal.Invoker.invokeTestMethod(Invoker.java:869)
	at org.testng.internal.Invoker.invokeTestMethods(Invoker.java:1193)
	at org.testng.internal.TestMethodWorker.invokeTestMethods(TestMethodWorker.java:126)
	at org.testng.internal.TestMethodWorker.run(TestMethodWorker.java:109)
	at org.testng.TestRunner.privateRun(TestRunner.java:744)
	at org.testng.TestRunner.run(TestRunner.java:602)
	at org.testng.SuiteRunner.runTest(SuiteRunner.java:380)
	at org.testng.SuiteRunner.runSequentially(SuiteRunner.java:375)
	at org.testng.SuiteRunner.privateRun(SuiteRunner.java:340)
	at org.testng.SuiteRunner.run(SuiteRunner.java:289)
	at org.testng.SuiteRunnerWorker.runSuite(SuiteRunnerWorker.java:52)
	at org.testng.SuiteRunnerWorker.run(SuiteRunnerWorker.java:86)
	at org.testng.TestNG.runSuitesSequentially(TestNG.java:1301)
	at org.testng.TestNG.runSuitesLocally(TestNG.java:1226)
	at org.testng.TestNG.runSuites(TestNG.java:1144)
	at org.testng.TestNG.run(TestNG.java:1115)
	at org.testng.remote.AbstractRemoteTestNG.run(AbstractRemoteTestNG.java:132)
	at org.testng.remote.RemoteTestNG.initAndRun(RemoteTestNG.java:230)
	at org.testng.remote.RemoteTestNG.main(RemoteTestNG.java:76)
]]>
    </failure>
  </testcase> <!-- luhn -->
  <testcase name="cvv" time="0.006" classname="core.CreditCardValidationTest"/>
  <testcase name="type" time="0.006" classname="core.CreditCardValidationTest"/>
  <testcase name="luhn" time="0.004" classname="core.CreditCardValidationTest">
    <failure type="java.lang.AssertionError" message="
Expected: Luhn of: 6011933302679615, should be valid
     but: was &lt;false&gt;">
      <![CDATA[java.lang.AssertionError: 
Expected: Luhn of: 6011933302679615, should be valid
     but: was <false>
	at org.hamcrest.MatcherAssert.assertThat(MatcherAssert.java:18)
	at org.hamcrest.MatcherAssert.assertThat(MatcherAssert.java:6)
	at core.CreditCardValidationTest.luhn(CreditCardValidationTest.java:41)
	at sun.reflect.NativeMethodAccessorImpl.invoke0(Native Method)
	at sun.reflect.NativeMethodAccessorImpl.invoke(Unknown Source)
	at sun.reflect.DelegatingMethodAccessorImpl.invoke(Unknown Source)
	at java.lang.reflect.Method.invoke(Unknown Source)
	at org.testng.internal.MethodInvocationHelper.invokeMethod(MethodInvocationHelper.java:108)
	at org.testng.internal.Invoker.invokeMethod(Invoker.java:661)
	at org.testng.internal.Invoker.invokeTestMethod(Invoker.java:869)
	at org.testng.internal.Invoker.invokeTestMethods(Invoker.java:1193)
	at org.testng.internal.TestMethodWorker.invokeTestMethods(TestMethodWorker.java:126)
	at org.testng.internal.TestMethodWorker.run(TestMethodWorker.java:109)
	at org.testng.TestRunner.privateRun(TestRunner.java:744)
	at org.testng.TestRunner.run(TestRunner.java:602)
	at org.testng.SuiteRunner.runTest(SuiteRunner.java:380)
	at org.testng.SuiteRunner.runSequentially(SuiteRunner.java:375)
	at org.testng.SuiteRunner.privateRun(SuiteRunner.java:340)
	at org.testng.SuiteRunner.run(SuiteRunner.java:289)
	at org.testng.SuiteRunnerWorker.runSuite(SuiteRunnerWorker.java:52)
	at org.testng.SuiteRunnerWorker.run(SuiteRunnerWorker.java:86)
	at org.testng.TestNG.runSuitesSequentially(TestNG.java:1301)
	at org.testng.TestNG.runSuitesLocally(TestNG.java:1226)
	at org.testng.TestNG.runSuites(TestNG.java:1144)
	at org.testng.TestNG.run(TestNG.java:1115)
	at org.testng.remote.AbstractRemoteTestNG.run(AbstractRemoteTestNG.java:132)
	at org.testng.remote.RemoteTestNG.initAndRun(RemoteTestNG.java:230)
	at org.testng.remote.RemoteTestNG.main(RemoteTestNG.java:76)
]]>
    </failure>
  </testcase> <!-- luhn -->
  <testcase name="exp" time="0.002" classname="core.CreditCardValidationTest"/>
  <testcase name="exp" time="0.004" classname="core.CreditCardValidationTest"/>
  <testcase name="type" time="0.003" classname="core.CreditCardValidationTest"/>
  <testcase name="type" time="0.102" classname="core.CreditCardValidationTest">
    <error type="org.testng.internal.reflect.MethodMatcherException" message="
Data provider mismatch
Method: type([Parameter{index=0, type=java.lang.String, declaredAnnotations=[]}, Parameter{index=1, type=java.lang.String, declaredAnnotations=[]}, Parameter{index=2, type=java.lang.String, declaredAnnotations=[]}, Parameter{index=3, type=java.lang.String, declaredAnnotations=[]}])
Arguments: [(java.lang.String)]">
      <![CDATA[org.testng.internal.reflect.MethodMatcherException: 
Data provider mismatch
Method: type([Parameter{index=0, type=java.lang.String, declaredAnnotations=[]}, Parameter{index=1, type=java.lang.String, declaredAnnotations=[]}, Parameter{index=2, type=java.lang.String, declaredAnnotations=[]}, Parameter{index=3, type=java.lang.String, declaredAnnotations=[]}])
Arguments: [(java.lang.String)]
	at org.testng.internal.reflect.DataProviderMethodMatcher.getConformingArguments(DataProviderMethodMatcher.java:49)
	at org.testng.internal.Invoker.injectParameters(Invoker.java:1293)
	at org.testng.internal.Invoker.invokeTestMethods(Invoker.java:1187)
	at org.testng.internal.TestMethodWorker.invokeTestMethods(TestMethodWorker.java:126)
	at org.testng.internal.TestMethodWorker.run(TestMethodWorker.java:109)
	at org.testng.TestRunner.privateRun(TestRunner.java:744)
	at org.testng.TestRunner.run(TestRunner.java:602)
	at org.testng.SuiteRunner.runTest(SuiteRunner.java:380)
	at org.testng.SuiteRunner.runSequentially(SuiteRunner.java:375)
	at org.testng.SuiteRunner.privateRun(SuiteRunner.java:340)
	at org.testng.SuiteRunner.run(SuiteRunner.java:289)
	at org.testng.SuiteRunnerWorker.runSuite(SuiteRunnerWorker.java:52)
	at org.testng.SuiteRunnerWorker.run(SuiteRunnerWorker.java:86)
	at org.testng.TestNG.runSuitesSequentially(TestNG.java:1301)
	at org.testng.TestNG.runSuitesLocally(TestNG.java:1226)
	at org.testng.TestNG.runSuites(TestNG.java:1144)
	at org.testng.TestNG.run(TestNG.java:1115)
	at org.testng.remote.AbstractRemoteTestNG.run(AbstractRemoteTestNG.java:132)
	at org.testng.remote.RemoteTestNG.initAndRun(RemoteTestNG.java:230)
	at org.testng.remote.RemoteTestNG.main(RemoteTestNG.java:76)
]]>
    </error>
  </testcase> <!-- type -->
  <testcase name="type" time="0.004" classname="core.CreditCardValidationTest"/>
  <testcase name="exp" time="0.000" classname="core.CreditCardValidationTest"/>
  <testcase name="luhn" time="0.003" classname="core.CreditCardValidationTest">
    <failure type="java.lang.AssertionError" message="
Expected: Luhn of: 6511933302679615, should be valid
     but: was &lt;false&gt;">
      <![CDATA[java.lang.AssertionError: 
Expected: Luhn of: 6511933302679615, should be valid
     but: was <false>
	at org.hamcrest.MatcherAssert.assertThat(MatcherAssert.java:18)
	at org.hamcrest.MatcherAssert.assertThat(MatcherAssert.java:6)
	at core.CreditCardValidationTest.luhn(CreditCardValidationTest.java:41)
	at sun.reflect.NativeMethodAccessorImpl.invoke0(Native Method)
	at sun.reflect.NativeMethodAccessorImpl.invoke(Unknown Source)
	at sun.reflect.DelegatingMethodAccessorImpl.invoke(Unknown Source)
	at java.lang.reflect.Method.invoke(Unknown Source)
	at org.testng.internal.MethodInvocationHelper.invokeMethod(MethodInvocationHelper.java:108)
	at org.testng.internal.Invoker.invokeMethod(Invoker.java:661)
	at org.testng.internal.Invoker.invokeTestMethod(Invoker.java:869)
	at org.testng.internal.Invoker.invokeTestMethods(Invoker.java:1193)
	at org.testng.internal.TestMethodWorker.invokeTestMethods(TestMethodWorker.java:126)
	at org.testng.internal.TestMethodWorker.run(TestMethodWorker.java:109)
	at org.testng.TestRunner.privateRun(TestRunner.java:744)
	at org.testng.TestRunner.run(TestRunner.java:602)
	at org.testng.SuiteRunner.runTest(SuiteRunner.java:380)
	at org.testng.SuiteRunner.runSequentially(SuiteRunner.java:375)
	at org.testng.SuiteRunner.privateRun(SuiteRunner.java:340)
	at org.testng.SuiteRunner.run(SuiteRunner.java:289)
	at org.testng.SuiteRunnerWorker.runSuite(SuiteRunnerWorker.java:52)
	at org.testng.SuiteRunnerWorker.run(SuiteRunnerWorker.java:86)
	at org.testng.TestNG.runSuitesSequentially(TestNG.java:1301)
	at org.testng.TestNG.runSuitesLocally(TestNG.java:1226)
	at org.testng.TestNG.runSuites(TestNG.java:1144)
	at org.testng.TestNG.run(TestNG.java:1115)
	at org.testng.remote.AbstractRemoteTestNG.run(AbstractRemoteTestNG.java:132)
	at org.testng.remote.RemoteTestNG.initAndRun(RemoteTestNG.java:230)
	at org.testng.remote.RemoteTestNG.main(RemoteTestNG.java:76)
]]>
    </failure>
  </testcase> <!-- luhn -->
  <testcase name="luhn" time="0.004" classname="core.CreditCardValidationTest"/>
  <testcase name="cvv" time="0.005" classname="core.CreditCardValidationTest"/>
  <testcase name="type" time="0.003" classname="core.CreditCardValidationTest"/>
</testsuite> <!-- core.CreditCardValidationTest -->
